Workbook

Sheet Overwiew 
B2: Conversion Technology | C2: Capacity Existing | D2: Capacity Limit | E2: OPEX | F2: CAPEX | G2: Carbon Footprint | H2: Notes
A3: Mineral Mining | B3: Bauxite mining | C3: yes | D3: 0 | E3: yes | F3: one value | G3: one value | H3: used CAPEX of copper/nickel mining
B4: Iron mining | C4: yes | D4: 0 | E4: yes | F4: one value | G4: one value | H4: used CAPEX of copper/nickel mining
B5: Nickel mining | C5: yes | D5: 0 | E5: yes | F5: one value | G5: one value
B6: Copper mining | C6: yes | D6: 0 | E6: yes | F6: one value | G6: yes
A7: Material Production | B7: Aluminium Production | C7: yes | D7: 0 | E7: yes | F7: one value | G7: yes
B8: Steel Production | C8: yes | D8: yes | E8: yes | F8: one value | G8: yes
B9: Copper Refinement | C9: yes | D9: 0 | E9: yes | F9: one value | G9: yes
A10: Component Manufacturing | B10: Compressor Manufacturing | C10: yes | D10: yes | E10: yes | F10: yes | G10: no
B11: HEX Manufacturing | C11: yes | D11: yes | E11: yes | F11: yes | G11: no
A12: Final Assembly | B12: HP Assembly | C12: yes | D12: yes | E12: yes | F12: yes | G12: no

Sheet compressor production
A1: Country | B1: year | C1: installed capacity | D1: unit | E1: type | F1: source | G1: Notes: | I1: Conversion of compressor prodcution | J1: Source: Rewlay-ngoen, 2020
A2: China | B2: 2018 | C2: =198*10^6 -> 198000000 | D2: units/year | E2: rotary compressor | F2: Nicholson,2019 | G2: specified for cooling | I2: Material type | J2: Component | K2: Weight | L2: Ratio | O2: https://www.bsria.com/us/news/article/world_compressor_market_an_overview/?srsltid=AfmBOoofS_VauHvF8VQmVHWe5OgWs4tQRiutDIwbD5xMriB5_O1y6Fwz
A3: Thailand | B3: 2018 | C3: =13*10^6 -> 13000000 | D3: units/year | E3: rotary compressor | F3: Nicholson,2019 | G3: specified for cooling | K3: (kg) | L3: (%)
A4: South Korea | B4: 2017 | C4: =5.5*10^6 -> 5500000 | D4: units/year | E4: rotary compressor | F4: Nicholson,2019 | G4: specified for cooling | I4: Cast iron | J4: Cylinder, shaft, rotor | K4: 4.8 | L4: 20.24
A5: Japan | B5: 2018 | C5: =4.1*10^6 -> 4100000 | D5: units/year | E5: rotary compressor | F5: Nicholson,2019 | G5: specified for cooling | I5: Steel sheet | J5: upper / lower housing, Accumulator | K5: 5.13 | L5: 21.64
A6: Malaysie | B6: 2018 | C6: =3.5*10^6 -> 3500000 | D6: units/year | E6: rotary compressor | F6: Nicholson,2019 | G6: specified for cooling | I6: High grade steel | J6: Rolling piston | K6: 0.56 | L6: 2.36
A7: Czech republik | B7: 2018 | C7: 790000 | D7: units/year | E7: rotary compressor | F7: Nicholson,2019 | G7: specified for cooling | I7: Sintering steel | J7: Upper / lower bearing | K7: 0.19 | L7: 0.8
A8: United states | B8: 2017 | C8: =1*10^6 -> 1000000 | D8: units/year | E8: rotary compressor | F8: Nicholson,2019 | G8: specified for cooling | I8: Silicon steel | J8: Stator, rotor | K8: 7.8 | L8: 32.9
A9: India | B9: 2017 | C9: =3*10^6 -> 3000000 | D9: units/year | E9: rotary compressor | F9: Nicholson,2019 | G9: specified for cooling | I9: Copper | J9: Copper wire | K9: 2.26 | L9: 9.53
A10: Brazil | B10: 2017 | C10: =1.9*10^6 -> 1900000 | D10: units/year | E10: rotary compressor | F10: Nicholson,2019 | G10: specified for cooling | J10: copper tube | K10: 0.44 | L10: 1.86
A11: europe | C11: =0.8*10^6 -> 800000 | D11: units/year | F11: Nicholson,2019 | I11: Aluminum ingot | J11: Rotor core | K11: 0.37 | L11: 1.56
A12: australia | C12: 8000 | D12: units/year | F12: Nicholson,2019 | I12: HCFC-22 (R22) | J12: Refrigerant | K12: 1.5 | L12: 6.33
A14: Country | B14: year | C14: Compressor Production Value | D14: unit | E14: source | F14: For Czechia | I14: Mineral oil | J14: Lubricant oil | K14: 0.653 | L14: 2.75
A15: Germany | B15: 2021 | C15: =805.9*10^6 -> 805900000 | D15: € | E15: ENEL, 2023 | F15: =C17/C7 -> 341.39241 | I15: Paint | J15: Compressor coating | K15: 0.008 | L15: 0.03
A16: Slovakia | B16: 2021 | C16: =349.1*10^6 -> 349100000 | D16: € | E16: ENEL, 2024 | I16: Total | K16: 23.711 | L16: 100
A17: Czechia | B17: 2021 | C17: =269.7*10^6 -> 269700000 | D17: € | E17: ENEL, 2025 | I17: Steel total | K17: =(K5+K6+K8+K7)/K16 -> 0.57694741 | L17: =L5+L6+L8+L7 -> 57.7 | M17: kg Steel/kg compressor
A18: Hungary | B18: 2021 | C18: =181.6*10^6 -> 181600000 | D18: € | E18: ENEL, 2026 | I18: Copper total | K18: =SUM(K9:K10)/K16 -> 0.1138712 | L18: =SUM(L9:L10) -> 11.39 | M18: kg Copper/kg compressor
A19: Itlay | B19: 2021 | C19: =166.4*10^6 -> 166400000 | D19: € | E19: ENEL, 2027 | I19: Umrechnungsfaktor von unit ro kW | K19: 2 | L19: kW/unit | M19: assumed COP of 3.5
A20: Spain | B20: 2021 | C20: =60.9*10^6 -> 60900000 | D20: € | E20: ENEL, 2028
A21: Europe | B21: 2024 | C21: =4.6*10^9*0.84 -> 3864000000 | D21: € | E21: https://www.gminsights.com/industry-analysis/europe-heat-pump-compressors-market
A22: World | C22: =486*10^6 -> 486000000 | D22: units | E22: https://www.bsria.com/us/news/article/world_compressor_market_an_overview/?srsltid=AfmBOoofS_VauHvF8VQmVHWe5OgWs4tQRiutDIwbD5xMriB5_O1y6Fwz
A23: World | C23: =42.4*10^9*0.84 -> 35616000000 | D23: € | E23: https://www.bsria.com/us/news/article/world_compressor_market_an_overview/?srsltid=AfmBOoofS_VauHvF8VQmVHWe5OgWs4tQRiutDIwbD5xMriB5_O1y6Fwz
A24: Country | B24: year | C24: sales volume | D24: unit | E24: Increased sales volume 2021-2023 | F24: source | G24: Notes:
A25: China | B25: 2023 | C25: =6673.5*1000 -> 6673500 | D25: units | E25: 0.024 | F25: http://www.chinaiol.com/download/Global%20Heat%20Pump%20Market%20Report%202024.pdf
B27: installed capacity | C27: €/yr | E27: unit | F27: Carbon footprint | I27: CAGR
A28: AUS | B28: =218*10^6*0.84 -> 183120000 | C28: €/yr | D28: =B28/'cost estimate'!$B$6*'cost estimate'!$B$31/10^6 -> 1.3025676 | E28: GW | I28: 0.059 | J28: https://www.nextmsc.com/report/australia-air-compressor-market#:~:text=The%20Australia%20Air%20Compressor%20Market,5.9%25%20from%202024%20to%202030.
A29: AUT | B29: 0 | C29: €/yr | D29: 0 | E29: GW | I29: 0.176 | J29: no data
A30: BRA | B30: =900*1000 -> 900000 | C30: units/year | D30: =B30*'cost estimate'!$B$31/10^6*$B$49 -> 7.2 | E30: GW | I30: 0.03 | J30: https://www.clasp.ngo/wp-content/uploads/2021/01/ENG-2018-Technical-and-Economic-Feasibility-Study-for-a-High-Efficiency-Compressor-Market-in-Brazil.pdf
A31: CHN | B31: =6673.5*1000 -> 6673500 | C31: units/year | D31: =B31*'cost estimate'!$B$31/10^6*$B$49 -> 53.388 | E31: GW | I31: 0.078 | J31: https://www.maximizemarketresearch.com/market-report/air-conditioning-compressor-market/169709/#:~:text=Air%20Conditioning%20Compressor%20Market%20–%20increasing,to%20boost%20the%20market%20growth&text=Air%20Conditioning%20Compressor%20Market%20size,5.2%20%25%20during%20the%20forecast%20period.
A32: CZE | B32: =269.7*10^6 -> 269700000 | C32: €/yr | D32: =B32/'cost estimate'!$B$6*'cost estimate'!$B$31/10^6 -> 1.9184277 | E32: GW | I32: 0.176
A33: DEU | B33: =805.9*10^6 -> 805900000 | C33: €/yr | D33: =B33/'cost estimate'!$B$6*'cost estimate'!$B$31/10^6 -> 5.732521 | E33: GW | I33: 0.176
A34: ITA | B34: =166.4*10^6 -> 166400000 | C34: €/yr | D34: =B34/'cost estimate'!$B$6*'cost estimate'!$B$31/10^6 -> 1.1836351 | E34: GW | I34: 0.176
A35: JPN | B35: =4.1*10^6 -> 4100000 | C35: units/year | D35: =B35*K19/10^6*$B$49 -> 8.2 | E35: GW | I35: 0.078 | J35: https://www.maximizemarketresearch.com/market-report/air-conditioning-compressor-market/169709/#:~:text=Air%20Conditioning%20Compressor%20Market%20–%20increasing,to%20boost%20the%20market%20growth&text=Air%20Conditioning%20Compressor%20Market%20size,5.2%20%25%20during%20the%20forecast%20period.
A36: KOR | B36: =754*10^6*0.84 -> 633360000 | C36: €/yr | D36: =B36/'cost estimate'!$B$6*'cost estimate'!$B$31/10^6 -> 4.505211 | E36: GW | I36: 0.078 | J36: https://www.grandviewresearch.com/horizon/outlook/air-compressor-market/south-korea
A37: ROE | B37: =(4.6*10^9*0.84-B32-B33-B34-B29) -> 2622000000 | C37: €/yr | D37: =B37/'cost estimate'!$B$6*'cost estimate'!$B$31/10^6 -> 18.650788 | E37: GW | F37: 850.33 | I37: 0.176 | J37: https://www.gminsights.com/industry-analysis/europe-heat-pump-compressors-market
A38: ROW | B38: =B51*10^9*0.84 -> 1.91184e+10 | C38: €/yr | D38: =(B38/'cost estimate'!$B$6*'cost estimate'!$B$31/10^6)-SUM(D28:D37,D39) -> 25.91169 | E38: GW | F38: 836.2 | G38: kg Co2-eq / 4 Kw compressor | H38: ecoinevent | I38: 0.13766667 | J38: https://www.maximizemarketresearch.com/market-report/air-conditioning-compressor-market/169709/#:~:text=Air%20Conditioning%20Compressor%20Market%20–%20increasing,to%20boost%20the%20market%20growth&text=Air%20Conditioning%20Compressor%20Market%20size,5.2%20%25%20during%20the%20forecast%20period.
A39: USA | B39: =1*10^6 -> 1000000 | C39: units/year | D39: =B39*'cost estimate'!$B$31/10^6*$B$49 -> 8 | E39: GW | I39: 0.057
A42: Market size compressors | B42: 46.7 | C42: 10^9 USD | D42: 5.3 | E42: https://www.bsria.com/us/news/article/world_compressor_market_an_overview/?srsltid=AfmBOoofS_VauHvF8VQmVHWe5OgWs4tQRiutDIwbD5xMriB5_O1y6Fwz | F42: 1% market share heat pump
A43: Market size compressors | B43: 25.9 | C43: 10^9 USD | D43: 5 | E43: https://www.futuremarketinsights.com/reports/air-conditioning-compressor-market
A44: Average market size compressors HVAC | B44: =AVERAGE(B42:B43) -> 36.3
...

Sheet Heat Exchanger
A1: Country | B1: Market value | C1: Unit | D1: Year | E1: CAGR | F1: Source | G1: Notes
A2: Europe | B2: =6000*0.84 -> 5040 | C2: Mio. € | D2: 2024 | E2: 0.042 | F2: https://www.imarcgroup.com/europe-heat-exchanger-market
B3: =8800*0.84 -> 7392 | C3: Mio. € | D3: 2032
A4: Europe | B4: 900 | C4: Mio. € | D4: 2024 | E4: 18.9 | F4: https://www.gminsights.com/industry-analysis/europe-heat-pump-brazed-plate-heat-exchangers-market | G4: value fopr brazed plate heat exchanger in HP used in AC
A5: Europe | B5: 4700 | C5: Mio. € | D5: 2032 | F5: https://www.gminsights.com/industry-analysis/europe-heat-pump-brazed-plate-heat-exchangers-market | G5: estimate
A6: Italy | B6: =B4*0.26 -> 234 | C6: Mio. € | D6: 2024 | F6: https://www.cbi.eu/sites/default/files/market-information/product-factsheet-europe-heat-exchangers-2016.pdf | G6: used share to estimate HP value in country
A7: Germany | B7: =B4*0.2 -> 180 | C7: Mio. € | D7: 2024 | F7: https://www.cbi.eu/sites/default/files/market-information/product-factsheet-europe-heat-exchangers-2016.pdf | G7: used share to estimate HP value in country
A8: France | B8: =B4*0.13 -> 117 | C8: Mio. € | D8: 2024 | F8: https://www.cbi.eu/sites/default/files/market-information/product-factsheet-europe-heat-exchangers-2016.pdf | G8: used share to estimate HP value in country
A9: Austria | B9: =B4*0.04 -> 36 | C9: Mio. € | D9: 2024 | F9: https://www.cbi.eu/sites/default/files/market-information/product-factsheet-europe-heat-exchangers-2016.pdf | G9: used share to estimate HP value in country
A10: Czech Republic | B10: =B4*0.03 -> 27 | C10: Mio. € | D10: 2024 | F10: https://www.cbi.eu/sites/default/files/market-information/product-factsheet-europe-heat-exchangers-2016.pdf | G10: used share to estimate HP value in country
A11: Sweden | B11: =0.09*B4 -> 81 | C11: Mio. € | D11: 2024
A12: China | B12: 4242.5 | C12: Mio. USD | D12: 2023 | E12: 0.065 | F12: https://www.nextmsc.com/report/china-heat-exchangers-market | G12: aound 30% of HX industry are in petroleum and chemical industry source: https://heat-exchanger-world.com/featured-story-the-fast-growing-heat-exchanger-market-in-china/)
A13: China | B13: 6872.1 | C13: Mio. USD | D13: 2030 | F13: https://www.nextmsc.com/report/china-heat-exchangers-market
A14: China | B14: =3.2*10^3 -> 3200 | C14: Mio. RMB | D14: 2021 | F14: http://www.chinaiol.com/download/Global%20Heat%20Pump%20Market%20Report%202024.pdf
B15: =B14/6.45 -> 496.12403 | C15: Mio. USD
A16: Australia | B16: 287.2 | C16: Mio. USD | D16: 2023 | F16: https://www.nextmsc.com/news/australia-heat-exchangers-market
A17: Australia | B17: 560.5 | C17: Mio. USD | D17: 2030 | E17: 0.094 | F17: https://www.nextmsc.com/news/australia-heat-exchangers-market
A18: global | B18: 17610 | C18: Mio. USD | D18: 2022 | F18: https://www.fortunebusinessinsights.com/industry-reports/heat-exchangers-market-100919#
A19: global | B19: =35.34*10^3 -> 35340 | C19: Mio. USD | D19: 2032 | E19: 0.0826 | F19: https://www.fortunebusinessinsights.com/industry-reports/heat-exchangers-market-100919#
A20: global | B20: 255000 | C20: Mio. USD | D20: 2030 | E20: 0.053 | F20: https://www.strategicmarketresearch.com/market-report/heat-exchangers-market#:~:text=The%20global%20heat%20exchanger%20market,to%20%2425.5%20billion%20by%202030.
A21: South korea | B21: 66.1 | C21: Mio USD | D21: 2023 | F21: https://www.grandviewresearch.com/horizon/outlook/plate-frame-heat-exchangers-market/south-korea
A22: South Korea | B22: 101.7 | C22: Mio USD | D22: 2030 | E22: 0.063 | F22: https://www.grandviewresearch.com/horizon/outlook/plate-frame-heat-exchangers-market/south-korea
A23: Japan | B23: 826.5 | C23: Mio USD | D23: 2023 | F23: https://www.nextmsc.com/report/japan-heat-exchangers-market
A24: Japan | B24: 1451.5 | C24: Mio USD | D24: 2030 | E24: 0.078 | F24: https://www.nextmsc.com/report/japan-heat-exchangers-market
A25: Brazil | B25: 158.1 | C25: Mio USD | D25: 2022 | F25: https://www.grandviewresearch.com/horizon/outlook/shell-and-tube-heat-exchanger-market/brazil
A26: Brazil | B26: 226.7 | C26: Mio USD | D26: 2030 | E26: 0.046 | F26: https://www.grandviewresearch.com/horizon/outlook/shell-and-tube-heat-exchanger-market/brazil
A27: USA | B27: 2700 | D27: 2022 | F27: https://www.grandviewresearch.com/industry-analysis/us-heat-exchangers-market-report
A28: USA | D28: 2030 | E28: 0.044 | F28: https://www.grandviewresearch.com/industry-analysis/us-heat-exchangers-market-report
A30: facror application HVAC to all applications
A31: Europe | B31: =B4/B2 -> 0.17857143
A32: China | B32: =B15/B12 -> 0.11694143
A33: Assumption | B33: 1 | C33: > based ont he sahre of e.g shell and tube -> sufficient if i found a source
C34: Market Value Current | D34: Per HX in HP | E34: In units production capacity per 8 kW HP (see cost sheet) | F34: Unit | G34: CAGR (2024 - 2032)
A35: AUS | B35: 2022 | C35: =B16*B33*0.84 -> 241.248 | D35: Mio. € | E35: =C35/'cost estimate'!$B$7*10^6 -> 335164.69 | F35: units HEX wit assumption 1 HX per 1 HP | G35: 0.094
A36: AUT | B36: 2022 | C36: 36 | D36: Mio. € | E36: =C36/'cost estimate'!$B$7*10^6 -> 50014.628 | F36: units HEX wit assumption 1 HX per 1 HP | G36: 0.189
A37: BRA | B37: 2022 | C37: =B25*0.84*B33 -> 132.804 | D37: Mio. € | E37: =C37/'cost estimate'!$B$7*10^6 -> 184503.96 | F37: units HEX wit assumption 1 HX per 1 HP | G37: 0.046
A38: CHN | B38: 2022 | C38: =B12*0.84 -> 3563.7 | D38: Mio. € | E38: =C38/'cost estimate'!$B$7*10^6 -> 4951031.3 | F38: units HEX wit assumption 1 HX per 1 HP | G38: 0.07
A39: CZE | B39: 2022 | C39: 27 | D39: Mio. € | E39: =C39/'cost estimate'!$B$7*10^6 -> 37510.971 | F39: units HEX wit assumption 1 HX per 1 HP | G39: 0.189
A40: DEU | B40: 2022 | C40: 180 | D40: Mio. € | E40: =C40/'cost estimate'!$B$7*10^6 -> 250073.14 | F40: units HEX wit assumption 1 HX per 1 HP | G40: 0.189
A41: ITA | B41: 2022 | C41: 234 | D41: Mio. € | E41: =C41/'cost estimate'!$B$7*10^6 -> 325095.08 | F41: units HEX wit assumption 1 HX per 1 HP | G41: 0.189
...

Sheet heat pump production
A1: Conversion | B1: (shamoushaki 2023) | G1: lifetime of heap tpumo around 18 yrr | H1: Source: energy perspective outllok
A2: Table S1. Inventory data for all phases of air-source heat pump
A3: Manufacturing
A4: Component | B4: Material | C4: Weight | E4: Unit | I4: Ref | K4: Explanation
A5: Evaporator and condenser | B5: Low-alloyed steel | C5: 32 | E5: kg | I5: Greening, Benjamin, and Adisa Azapagic. "Domestic heat pumps: Life cycle environmental impacts and potential implications for the UK." Energy 39, no. 1 (2012): 205-217.
A6: Housing and compressor | B6: Reinforcing steel | C6: 120 | E6: kg | I6: Sevindik, Selman, Catalina Spataru, Teresa Domenech Aparisi, and Raimund Bleischwitz. "A comparative environmental assessment of heat pumps and gas boilers towards a circular economy in the UK." Energies 14, no. 11 (2021): 3027.
A7: Wiring, piping and expansion valve | B7: Copper | C7: 35.2 | E7: kg | I7: " | K7: UK data
A8: Pipework insulation | B8: Elastomere | C8: 16 | E8: kg | I8: " | K8: Data for a 10 kW ASHP ?
A9: Wiring insulation | B9: Polyvinylchloride | C9: 1.6 | E9: kg | I9: "
A10: Lubricating oil | B10: Polyolester oil | C10: 2.7 | E10: kg | I10: "
A11: Air fan | B11: Copper | C11: 1.4 | E11: kg | I11: "
A12: " | B12: HDPE | C12: 0.5 | E12: kg | I12: "
A13: Refrigerant | B13: R-134a | C13: 4.9 | E13: kg | I13: "
A14: " | B14: Losses | C14: 3% (manufacture) & 6% (operation, annually)
A15: Energy | B15: Medium-voltage electricity | C15: 504 | E15: MJ | I15: Naumann, Gabriel, Elke Schropp, and Matthias Gaderer. "Life Cycle Assessment of an Air-Source Heat Pump and a Condensing Gas Boiler Using an Attributional and a Consequential Approach." Procedia CIRP 105 (2022): 351-356. | K15: Data for a 5 kW ASHP ?
A16: " | B16: Heat | C16: 1400 | E16: MJ | I16: Naumann, Gabriel, Elke Schropp, and Matthias Gaderer. "Life Cycle Assessment of an Air-Source Heat Pump and a Condensing Gas Boiler Using an Attributional and a Consequential Approach." Procedia CIRP 105 (2022): 351-356.
A17: Assembly & Installation
A18: Process | B18: Energy | C18: Weight | E18: Unit | I18: Ref
A19: Assembly | B19: Medium-voltage electricity (European mix) | C19: 504 | E19: MJ | I19: Greening, Benjamin, and Adisa Azapagic. "Domestic heat pumps: Life cycle environmental impacts and potential implications for the UK." Energy 39, no. 1 (2012): 205-217.
A20: " | B20: Natural gas | C20: 1400 | E20: MJ | I20: Sevindik, Selman, Catalina Spataru, Teresa Domenech Aparisi, and Raimund Bleischwitz. "A comparative environmental assessment of heat pumps and gas boilers towards a circular economy in the UK." Energies 14, no. 11 (2021): 3027. | K20: Explanation
A21: O & M
A22: Process/Item | B22: Weight | C22: Unit | E22: Ref
A23: UK electricity | B23: 0.357 | C23: kWh/kWh heat generated | E23: Greening, Benjamin, and Adisa Azapagic. "Domestic heat pumps: Life cycle environmental impacts and potential implications for the UK." Energy 39, no. 1 (2012): 205-217.
A24: Refrigerant | B24: 0.294 | C24: kg (annually) | E24: Sevindik, Selman, Catalina Spataru, Teresa Domenech Aparisi, and Raimund Bleischwitz. "A comparative environmental assessment of heat pumps and gas boilers towards a circular economy in the UK." Energies 14, no. 11 (2021): 3027.
A25: Air‐source heat pumps for residential applications contain around 15 to 20 kilogrammes of copper, predominantly in their pipes and valves, making up roughly 10% of the overall cost of the devic
A26: souzrce (the future of heat pumps, 2022
A28: Production installment duration | B28: 1-3 y | C28: y | E28: Source: https://www.iea.org/energy-system/buildings/heat-pumps#tracking | L28: Planned Investment
A30: Country | B30: Capacity installed | C30: unit | E30: year | G30: source | H30: if estimated on a 8kw HP | J30: Notes | K30: Capacity estimated 2030 | L30: unit | M30: Source | N30: CAPEX for heat pump facilites
A31: China | B31: 50 | C31: GW | E31: 2024 | G31: IEA, https://www.iea.org/data-and-statistics/charts/heat-pump-manufacturing-capacity-per-region-2022 | H31: =B31*10^6/8 -> 6250000 | I31: units HP | J31: 20 for Air-Air GW and 30 air to water (IEA; china heat pumps) | K31: =B31*1.2 -> 60 | L31: GW | N31: =60*0.84 -> 50.4 | O31: €/kW | P31: IEA clean technology outlook 2023
A32: US | B32: 34 | C32: GW | E32: 2024 | G32: IEA, https://www.iea.org/data-and-statistics/charts/heat-pump-manufacturing-capacity-per-region-2023 | H32: =B32*10^6/8 -> 4250000 | K32: =B32*1.2 -> 40.8 | L32: GW | N32: =175*0.84 -> 147 | O32: €/kW | P32: IEA clean technology outlook 2024
A33: Europe | B33: 25 | C33: GW | E33: 2024 | G33: IEA, https://www.iea.org/data-and-statistics/charts/heat-pump-manufacturing-capacity-per-region-2024 | H33: =B33*10^6/8 -> 3125000 | K33: =B33*1.2 -> 30 | L33: GW | N33: =170*0.84 -> 142.8 | O33: €/kW | P33: IEA clean technology outlook 2025
A34: Japan and Korea | B34: 16 | C34: GW | E34: 2024 | G34: IEA, https://www.iea.org/data-and-statistics/charts/heat-pump-manufacturing-capacity-per-region-2025 | H34: =B34*10^6/8 -> 2000000 | K34: =B34*1.2 -> 19.2 | L34: GW
A35: Japan | B35: =B34*Demand!I38/SUM(Demand!I38:J38) -> 9.1382105 | C35: GW | G35: allocation based on demand data as a rough estimate | H35: =B35*10^6/8 -> 1142276.3
A36: Korea | B36: =B34-B35 -> 6.8617895 | C36: GW | G36: allocation based on demand data as a rough estimate | H36: =B36*10^6/8 -> 857723.69
A37: ROW | B37: 14 | C37: GW | E37: 2024 | G37: IEA, https://www.iea.org/data-and-statistics/charts/heat-pump-manufacturing-capacity-per-region-2026 | H37: =B37*10^6/8 -> 1750000 | K37: =B37*1.2 -> 16.8 | L37: GW
A38: ROW w/o Australia | B38: =14-B45 -> 14 | H38: =H37-H45 -> 1486000
A39: Brazil | B39: 0 | C39: GW | E39: 2024 | G39: IEA Energy Technology Perspectives 2023, page 453 (annex) | H39: =B39*10^6/8 -> 0 | K39: =B39*1.2 -> 0 | L39: GW
A40: Germany | B40: =0.17*B33 -> 4.25 | C40: GW | H40: =B40*10^6/8 -> 531250
A41: Austria | B41: =0.06*B33 -> 1.5 | C41: GW | H41: =B41*10^6/8 -> 187500
A42: Italy | B42: =0.16*B33 -> 4 | C42: GW | H42: =B42*10^6/8 -> 500000
...

Sheet conversion
A1: conversion factors | U1: Lifecycle inventories of heating
A3: Conversion | B3: (shamoushaki 2023) | E3: probably for a 10 kW output
A4: Table S1. Inventory data for all phases of air-source heat pump
A5: Manufacturing
A6: Component | B6: Material | C6: Weight | D6: Unit | F6: Conversion of compressor prodcution | G6: Source: Rewlay-ngoen, 2020
A7: Evaporator and condenser | B7: Low-alloyed steel | C7: 32 | D7: kg | E7: assume half aluminium and half copper?? Mentioned in EC JRC 2023 | F7: Material type | G7: Component | H7: Weight | I7: Ratio
A8: Housing and compressor | B8: Reinforcing steel | C8: 120 | D8: kg | H8: (kg) | I8: (%)
A9: Wiring, piping and expansion valve | B9: Copper | C9: 35.2 | D9: kg | F9: Cast iron | G9: Cylinder, shaft, rotor | H9: 4.8 | I9: 20.24
A10: Pipework insulation | B10: Elastomere | C10: 16 | D10: kg | F10: Steel sheet | G10: upper / lower housing, Accumulator | H10: 5.13 | I10: 21.64
A11: Wiring insulation | B11: Polyvinylchloride | C11: 1.6 | D11: kg | F11: High grade steel | G11: Rolling piston | H11: 0.56 | I11: 2.36
A12: Lubricating oil | B12: Polyolester oil | C12: 2.7 | D12: kg | F12: Sintering steel | G12: Upper / lower bearing | H12: 0.19 | I12: 0.8
A13: Air fan | B13: Copper | C13: 1.4 | D13: kg | F13: Silicon steel | G13: Stator, rotor | H13: 7.8 | I13: 32.9
A14: " | B14: HDPE | C14: 0.5 | D14: kg | F14: Copper | G14: Copper wire | H14: 2.26 | I14: 9.53
A15: Refrigerant | B15: R-134a | C15: 4.9 | D15: kg | G15: copper tube | H15: 0.44 | I15: 1.86
A16: " | B16: Losses | C16: 3% (manufacture) & 6% (operation, annually) | F16: Aluminum ingot | G16: Rotor core | H16: 0.37 | I16: 1.56
A17: Energy | B17: Medium-voltage electricity | C17: 504 | D17: MJ | F17: HCFC-22 (R22) | G17: Refrigerant | H17: 1.5 | I17: 6.33
A18: " | B18: Heat | C18: 1400 | D18: MJ | F18: Mineral oil | G18: Lubricant oil | H18: 0.653 | I18: 2.75
A19: Assembly & Installation | F19: Paint | G19: Compressor coating | H19: 0.008 | I19: 0.03
A20: Process | B20: Energy | C20: Weight | D20: Unit | F20: Total | H20: 23.711 | I20: 100
A21: Assembly | B21: Medium-voltage electricity (European mix) | C21: 504 | D21: MJ | F21: Steel total | H21: =(H10+H11+H13+H12)/H20 -> 0.57694741 | I21: =I10+I11+I13+I12 -> 57.7 | J21: kg Steel/kg compressor
A22: " | B22: Natural gas | C22: 1400 | D22: MJ | F22: Copper total | H22: =SUM(H14:H15)/H20 -> 0.1138712 | I22: =SUM(I14:I15) -> 11.39 | J22: kg Copper/kg compressor
A23: O & M
A24: Process/Item | B24: Weight | C24: Unit | D24: Ref
A25: UK electricity | B25: 0.357 | C25: kWh/kWh heat generated | D25: Greening, Benjamin, and Adisa Azapagic. "Domestic heat pumps: Life cycle environmental impacts and potential implications for the UK." Energy 39, no. 1 (2012): 205-217.
A26: Refrigerant | B26: 0.294 | C26: kg (annually) | D26: Sevindik, Selman, Catalina Spataru, Teresa Domenech Aparisi, and Raimund Bleischwitz. "A comparative environmental assessment of heat pumps and gas boilers towards a circular economy in the UK." Energies 14, no. 11 (2021): 3027.
A27: Air‐source heat pumps for residential applications contain around 15 to 20 kilogrammes of copper, predominantly in their pipes and valves, making up roughly 10% of the overall cost of the devic
A30: Average HP | C30: unit | D30: per Fu of 8 W | G30: Demand 2035 | I30: demand 2022 | J30: Bauxite
A31: Aluminum | B31: 32.3 | C31: kg/HP | D31: =B31/'cost estimate'!B31 -> 4.0375 | E31: kg/kW | F31: https://21255462.fs1.hubspotusercontent-na1.net/hubfs/21255462/Reports%20-%20Research/BZE%202024%20-%20Heat%20Pumps%20Supply%20Chain%20Briefing%20Paper.pdf?utm_medium=email&_hsenc=p2ANqtz-9dM8q358vgTGkDybe5e7jgnidtYeyNJEe5lIx4vgFMrCjajGmjMZRA6pWnNwM3C8x8xaJyVpqTPY3p2QLWycjpnTHNBw&_hsmi=295770870&utm_content=295770870&utm_source=hs_automation | G31: =D31*Demand!$N$68/10^6 -> 1519.4847 | H31: kt/a | I31: =D31*SUM(Demand!$B$55:$M$55)/10^6 -> 448.1625 | J31: =I31*4 -> 1792.65 | K31: =G31*1500 -> 2279227
A32: Steel | B32: =AVERAGE(C7+C8,146.9) -> 149.45 | C32: kg/HP | D32: =B32/'cost estimate'!$B$31 -> 18.68125 | E32: kg/kW | G32: =D32*Demand!$N$68/10^6 -> 7030.5569 | H32: kt/a | I32: =D32*SUM(Demand!$B$55:$M$55)/10^6 -> 2073.6187 | K32: =G32*400 -> 2812222.8 | L32: =K31/K32 -> 0.81047173
A33: Copper | B33: =AVERAGE(C9+C13,36.6,59.2) -> 44.133333 | C33: kg/HP | D33: =B33/'cost estimate'!$B$31 -> 5.5166667 | E33: kg/kW | G33: =D33*Demand!$N$68/10^6 -> 2076.1587 | H33: kt/a | I33: =D33*SUM(Demand!$B$55:$M$55)/10^6 -> 612.35 | K33: =G33*1500 -> 3114238
A34: Nickel | B34: =B31*0.15 -> 4.845 | C34: kg/HP | D34: =B34/'cost estimate'!$B$31 -> 0.605625 | E34: kg/kW | F34: Assume nickel in alloyed steel | G34: =D34*Demand!$N$68/10^6 -> 227.9227 | H34: kt/a | I34: =D34*SUM(Demand!$B$55:$M$55)/10^6 -> 67.224375 | K34: =G34*1500 -> 341884.06
A35: copper of which are in compressor | B35: =I22 -> 11.39 | C35: kg/HP | D35: =B35/'cost estimate'!$B$31 -> 1.42375 | E35: kg/kW
A36: copper in rest of hp | B36: =B33-B35 -> 32.743333 | C36: kg/HP | D36: =B36/'cost estimate'!$B$31 -> 4.0929167 | E36: kg/kW
A37: steel in compressot | B37: =I21 -> 57.7 | C37: kg/HP | D37: =B37/'cost estimate'!$B$31 -> 7.2125 | E37: kg/kW
A38: Steel rest in HP | B38: =B32-B37 -> 91.75 | C38: kg/HP | D38: =B38/'cost estimate'!$B$31 -> 11.46875 | E38: kg/kW | G38: =1351959+135185+942882 -> 2430026
A39: Refrigerant | B39: =AVERAGE(C15,4.9,4.9,3.5) -> 4.55 | C39: kg/HP | D39: =B39/'cost estimate'!$B$31 -> 0.56875 | E39: kg/kW | G39: =2794175+27982 -> 2822157
M49: From EC JRC Report (page 43):

Sheet cost estimate
A3: cost of heat pump 8Kw | C3: to estimate market value | D3: in €/kW
A4: UK example | B4: 3760 | C4: Punds | E4: https://www.sciencedirect.com/science/article/pii/S2211467X2400227X
B5: =B4/O46 -> 4498.6839 | C5: Euros/HP
A6: Share compressor | B6: =B5*0.25 -> 1124.671 | C6: Euros/HP or Euros /8kW | D6: =B6/8 -> 140.58387 | E6: Heat Pump Supply Chains and Manufacturing Competitiveness Considerations
A7: sahre HX | B7: =B5*0.16 -> 719.78942 | C7: Euros/HP or Euros /8kW | D7: =B7/8 -> 89.973678 | E7: Heat Pump Supply Chains and Manufacturing Competitiveness Considerations (Margaret Mann, 2016)
A8: sahre refrigerant | B8: =0.02*B5/conversion!B39 -> 19.774435 | C8: Euro/kg refrigerant | D8: =B8/8 -> 2.4718043 | E8: Heat Pump Supply Chains and Manufacturing Competitiveness Considerations (Margaret Mann, 2016)
A10: year | B10: price_shed_demand
A11: 2022 | B11: "inf"
A12: 2023 | B12: "inf"
A13: 2024 | B13: "inf"
A14: 2025 | B14: "inf"
A15: 2026 | B15: "inf"
A16: 2027 | B16: "inf"
A17: 2028 | B17: "inf"
A18: 2029 | B18: "inf"
A19: 2030 | B19: "inf"
A20: 2031 | B20: "inf"
A21: 2032 | B21: "inf"
A22: 2033 | B22: =140*11.5 -> 1610 | C22: €/kW
A23: 2034 | B23: =140*11.5 -> 1610 | C23: €/kW
A24: 2035 | B24: =140*11.5 -> 1610 | C24: €/kW
A29: Assumption for conversino
A30: HP | B30: kW
A31: 1 | B31: 8
A33: Regionalized cost factors
A34: For Labour | B34: €/h | C34: Labour adjusment factor
A35: Australia | B35: 38.19 | C35: =B35/$B$46 -> 1.3895082
A36: Austria | B36: 39.54 | C36: =B36/$B$46 -> 1.4386267
A37: Brazil | B37: 7.98 | C37: =B37/$B$46 -> 0.29034499
A38: China | B38: =B45/3 -> 13.3 | C38: =B38/$B$46 -> 0.48390831
A39: Czech republic | B39: 10.71 | C39: =B39/$B$46 -> 0.38967354
A40: Germany | B40: 43.18 | C40: =B40/$B$46 -> 1.5710647
A41: Italy | B41: 32.49 | C41: =B41/$B$46 -> 1.1821189 | E41: =AVERAGE(C35,C49) -> 1.2264618
A42: Japan | B42: 26.46 | C42: =B42/$B$46 -> 0.96272285 | E42: =AVERAGE(C36,C50) -> 1.4204663
A43: Korea | B43: 22.98 | C43: =B43/$B$46 -> 0.83610624 | E43: =AVERAGE(C37,C51) -> 0.44511017
A44: Rest of Europe | B44: 27.6 | C44: =B44/$B$46 -> 1.0042007 | E44: =AVERAGE(C38,C52) -> 0.39387064 | N44: converison factor
A45: USA | B45: 39.9 | C45: =B45/$B$46 -> 1.4517249 | E45: =AVERAGE(C39,C53) -> 0.89404213 | N45: euro | O45: 1 | Q45: https://www.currency.me.uk/convert/eur/gbp#:~:text=Latest%20Currency%20Exchange%20Rates%3A%201%20Euro%20%3D%200.8358%20British%20Pound
B46: =AVERAGE(B35:B45) -> 27.484545 | E46: =AVERAGE(C40,C54) -> 1.4964236 | N46: pound | O46: 0.8358
E47: =AVERAGE(C41,C55) -> 1.4811342
A48: For Energy Cost | B48: USD/kWh | C48: Energy adjusment factor | E48: =AVERAGE(C42,C56) -> 0.91179147
...

Sheet Jobs
A1: Country | B1: Jobs | C1: Type | D1: Year | E1: Source | F1: Projected workforce 2030 | G1: Notes | H1: Source
A2: Europe | B2: 44000 | C2: heat pump manufacturing | D2: 2022 | E2: EHPA 2022
A3: Europe | B3: 22000 | C3: component manufacturing | D3: 2022 | E3: EHPA 2022
A4: China | B4: 100000 | C4: Manufacturing | D4: 2022 | E4: IEA, Outlook Heat pump china | F4: 200000 | G4: extra workers in the sector | H4: IEA, HP in China
A6: Global | B6: 810000 | C6: in HP supply chain | D6: 2022 | E6: IEA, Outlook Heat pump china
A8: australia | B8: 7000 | C8: in HP manufacturing | D8: 2030 | E8: https://21255462.fs1.hubspotusercontent-na1.net/hubfs/21255462/Reports%20-%20Research/BZE%202024%20-%20Make%20it%20Here%20Building%20Australias%20Clean%20Industrial%20Future%20.pdf?utm_medium=email&_hsenc=p2ANqtz-830lZIoJiepzUI-y6CKlT2VKway4PaFo_35Km9xKs-JjEI34UFgSiLcYE4S5qALQvqTJZSZ2a2d6oBJgafaoQ4Rw4QzA&_hsmi=305939647&utm_content=305939647&utm_source=hs_automation
A12: Steel | B12: 6 | C12: Mio. Jobs
A13: in europe | B13: 330000 | C13: jobs
A14: australoa | B14: 100000 | C14: jobs
I22: lbaor prodoctivity | J22: https://mcusercontent.com/8dbf465d9a5cfe9f310f1464e/files/aefa3988-2475-e868-fb82-c5a0af13dbaa/EU_Hydronic_Heat_Pump_Manufacturing_Market_Assessment_Technical_Report.pdf

Sheet Demand
A2: Country | B2: Sales of heating heat pumps 2022 | C2: Growth in sales 2021 to 2022 (% of additional heat pumps units sold) | D2: Growth in sales 2021 to 2022 (no. of additional heat pumps units sold) | E2: Source | F2: https://www.ehpa.org/wp-content/uploads/2023/06/Heat-Pump-Key-Facts-May-2023_compressed.pdf | G2: Country | H2: Sales/value | I2: Unit | J2: year | K2: Source | L2: Annual grth rate IEA | M2: CAGR | N2: Sales in ASHP | O2: Sales in GSHP | P2: Source | Q2: Projected Value in 2030 | R2: Pojected sales in 2050 | S2: Source
A3: Austria | B3: 49204 | C3: 0.59 | D3: 18227 | E3: EHPA, 2023 | G3: Japan | H3: 746000 | I3: units | J3: 2021 | K3: https://heatpumpingtechnologies.org/wp-content/uploads/2023/03/mcr-iea-hpt-presentation-japan-20230314.pdf | L3: A
G4: South Korea | H4: =3*10^9 -> 3000000000 | I4: USD, value | J4: 2022 | K4: https://heatpumpingtechnologies.org/wp-content/uploads/2022/08/iea-hpt-tcp-member-country-report-korea-2022minsung-kim.pdf | L4: A
A5: Belgium | B5: 32965 | C5: 0.66 | D5: 13121 | E5: EHPA, 2023 | G5: USA | H5: =4.33*10^6 -> 4330000 | I5: units | J5: 2022 | K5: https://heatpumpingtechnologies.org/wp-content/uploads/2023/06/us-country-report-2023.pdf | L5: A
G6: USA | H6: 30 | I6: GW | J6: 2022 | K6: IEA, 2024 | L6: A | Q6: =H7*2 -> 62 | S6: https://iea.blob.core.windows.net/assets/217e820f-3344-4144-9d2c-cc444e080421/FutureofHeatpumpsinChina.pdf
A7: Czechia | B7: 60065 | C7: 0.99 | D7: 29886 | E7: EHPA, 2023 | G7: China | H7: 31 | I7: GW | J7: 2022 | K7: https://www.iea.org/reports/the-future-of-heat-pumps-in-china/executive-summary | L7: A | M7: 0.04
G8: China | H8: 1000000 | I8: units | J8: 2022 | K8: https://www.heatpumps.london/blog/everything-you-need-to-know-about-heat-pumps | L8: A
G9: China | H9: =31*10^9 -> 31000000000 | I9: RMB | J9: 2022 | K9: http://www.chinaiol.com/download/Global%20Heat%20Pump%20Market%20Report%202024.pdf | L9: this includes HP and AC split systems
A10: Denmark | B10: 88833 | C10: 0.2 | D10: 14892 | E10: EHPA, 2023 | G10: Australia | H10: =1.32*10^6 -> 1320000 | I10: units | J10: 2022 | K10: https://iifiir.org/en/news/main-figures-for-the-australian-heat-pump-market#:~:text=Single%20split%20system%20sales%20were,commercial%20heat%20pumps%20is%20small. | L10: 50% in Aitr to water and 20 percent in air to air | N10: =1800*10^3 -> 1800000 | P10: http://www.chinaiol.com/download/Global%20Heat%20Pump%20Market%20Report%202024.pdf | Q10: =7*10^6 -> 7000000 | S10: https://mcusercontent.com/8dbf465d9a5cfe9f310f1464e/files/aefa3988-2475-e868-fb82-c5a0af13dbaa/EU_Hydronic_Heat_Pump_Manufacturing_Market_Assessment_Technical_Report.pdf
G11: Europe | H11: =3*10^6 -> 3000000 | I11: units | J11: 2022 | K11: https://mcusercontent.com/8dbf465d9a5cfe9f310f1464e/files/aefa3988-2475-e868-fb82-c5a0af13dbaa/EU_Hydronic_Heat_Pump_Manufacturing_Market_Assessment_Technical_Report.pdf | L11: 24 air to water and 8% in ata; 1000 GW in cumulative capacity | Q11: 25000 | R11: 60000 | S11: https://mcusercontent.com/8dbf465d9a5cfe9f310f1464e/files/aefa3988-2475-e868-fb82-c5a0af13dbaa/EU_Hydronic_Heat_Pump_Manufacturing_Market_Assessment_Technical_Report.pdf
A12: Finland | B12: 196359 | C12: 0.52 | D12: 66984 | E12: EHPA, 2023 | G12: global cumulative | H12: 1000 | I12: GW | J12: 2021 | K12: https://mcusercontent.com/8dbf465d9a5cfe9f310f1464e/files/aefa3988-2475-e868-fb82-c5a0af13dbaa/EU_Hydronic_Heat_Pump_Manufacturing_Market_Assessment_Technical_Report.pdf
G13: global yearly | H13: 111 | I13: GW | K13: IEA
A14: France | B14: 462672 | C14: 0.2 | D14: 76176 | E14: EHPA, 2023 | G14: calculated: | H14: =H13*10^6/8 -> 13875000 | I14: units sold | K14: validation in https://21255462.fs1.hubspotusercontent-na1.net/hubfs/21255462/Reports%20-%20Research/BZE%202024%20-%20Heat%20Pumps%20Supply%20Chain%20Briefing%20Paper.pdf?utm_medium=email&_hsenc=p2ANqtz-9dM8q358vgTGkDybe5e7jgnidtYeyNJEe5lIx4vgFMrCjajGmjMZRA6pWnNwM3C8x8xaJyVpqTPY3p2QLWycjpnTHNBw&_hsmi=295770870&utm_content=295770870&utm_source=hs_automation
G15: global | H15: =8*10^6 -> 8000000 | I15: units sold | J15: 2020 | K15: lyons 2023
A16: Germany | B16: 236000 | C16: 0.53 | D16: 82000 | E16: EHPA, 2023
A18: Italy | B18: 502349 | C18: 0.37 | D18: 134429 | E18: EHPA, 2023
H19: Growth Rate | K19: europe is fastes growing HP market
A20: Netherlands | B20: 123208 | C20: 0.8 | D20: 54796 | E20: EHPA, 2023 | G20: Europe | H20: 0.17 | I20: CAGR | J20: ( https://eur-lex.europa.eu/legal-content/EN/TXT/?uri=CELEX%3A52022DC0643&qid=1669913060946)
G21: Oceania | H21: 0.04 | I21: CAGR | J21: https://iifiir.org/en/news/main-figures-for-the-australian-heat-pump-market#:~:text=Single%20split%20system%20sales%20were,commercial%20heat%20pumps%20is%20small.
A22: Norway | B22: 156295 | C22: 0.25 | D22: 31267 | E22: EHPA, 2023 | G22: North America | H22: 0.088 | I22: CAGR | J22: https://www.news.market.us/heat-pump-statistics/
G23: Asia | H23: 0.125 | I23: YoY | J23: http://www.chinaiol.com/download/Global%20Heat%20Pump%20Market%20Report%202024.pdf
A24: Poland | B24: 195480 | C24: 1.02 | D24: 98540 | E24: EHPA, 2023 | G24: Global | H24: 0.11 | I24: YoY | J24: https://www.iea.org/commentaries/global-heat-pump-sales-continue-double-digit-growth
G25: China | H25: =(35/31)^(1/4)-1 -> 0.030805169 | I25: CAGR | J25: calulated from data from iEA https://www.iea.org/reports/the-future-of-heat-pumps-in-china/executive-summary
A26: Portugal | B26: 29969 | C26: 0.17 | D26: 4357 | E26: EHPA, 2023 | G26: Global | H26: =(111/84)^(1/4)-1 -> 0.072163265 | I26: CAGR | J26: calulated from data from iEA https://www.iea.org/reports/the-future-of-heat-pumps-in-china/executive-summary | U26: https://iea.blob.core.windows.net/assets/217e820f-3344-4144-9d2c-cc444e080421/FutureofHeatpumpsinChina.pdf
U27: http://www.chinaiol.com/download/Global%20Heat%20Pump%20Market%20Report%202024.pdf
A28: Sweden*** | B28: 215373 | C28: 0.6 | D28: 81875 | E28: EHPA, 2023
A30: Switzerland | B30: 41209 | C30: 0.22 | D30: 7505 | E30: EHPA, 2023
A32: Spain | B32: 161800 | C32: 0.21 | D32: 28129 | E32: EHPA, 2023
A34: UK**** | B34: 59862 | C34: 0.4 | D34: 17103 | E34: EHPA, 2023
A36: Scenario 1: continue with current growth rate in unit pcs.
A37: year | B37: AUS | C37: AUT | D37: BRA | E37: CHN | F37: CZE | G37: DEU | H37: ITA | I37: JPN | J37: KOR | K37: ROE | L37: ROW | M37: USA | N37: unit
A38: 2022 | B38: =1.32*10^6 -> 1320000 | C38: 49204 | D38: 0 | E38: 1000000 | F38: 60065 | G38: 236000 | H38: 502349 | I38: 746000 | J38: =H4/'cost estimate'!B5*0.84 -> 560163.83 | K38: =H11-SUM(F38:H38,C38) -> 2152382 | L38: =H14-SUM(B38:K38,M38) -> 2918836.2 | M38: =4.33*10^6 -> 4330000 | N38: pcs
A39: 2023 | B39: =$B$38*($H$21+1)^(A39-$A$38) -> 1372800 | C39: =$C$38*(1+$H$20)^(A39-$A$38) -> 57568.68 | D39: 0 | E39: =$E$38*(1+$H$23)^(A39-$A$38) -> 1125000 | F39: =$F$38*(1+$H$20)^(A39-$A$38) -> 70276.05 | G39: =$G$38*(1+$H$20)^(A39-$A$38) -> 276120 | H39: =$H$38*(1+$H$20)^(A39-$A$38) -> 587748.33 | I39: =$I$38*(1+$H$23)^((A39-$A$38)) -> 839250 | J39: =$J$38*(1+$H$23)^((A39-$A$38)) -> 630184.31 | K39: =$K$38*(1+$H$20)^(A39-$A$38) -> 2518286.9 | L39: =$L$38*(1+$H$24)^(A39-$A$38) -> 3239908.1 | M39: =$M$38*(1+$H$22)^((A39-$A$38)) -> 4711040 | N39: pcs
A40: 2024 | B40: =$B$38*($H$21+1)^(A40-$A$38) -> 1427712 | C40: =$C$38*(1+$H$20)^(A40-$A$38) -> 67355.356 | D40: 0 | E40: =$E$38*(1+$H$23)^(A40-$A$38) -> 1265625 | F40: =$F$38*(1+$H$20)^(A40-$A$38) -> 82222.978 | G40: =$G$38*(1+$H$20)^(A40-$A$38) -> 323060.4 | H40: =$H$38*(1+$H$20)^(A40-$A$38) -> 687665.55 | I40: =$I$38*(1+$H$23)^((A40-$A$38)) -> 944156.25 | J40: =$J$38*(1+$H$23)^((A40-$A$38)) -> 708957.35 | K40: =$K$38*(1+$H$20)^(A40-$A$38) -> 2946395.7 | L40: =$L$38*(1+$H$24)^(A40-$A$38) -> 3596298 | M40: =$M$38*(1+$H$22)^((A40-$A$38)) -> 5125611.5 | N40: pcs
A41: 2025 | B41: =$B$38*($H$21+1)^(A41-$A$38) -> 1484820.5 | C41: =$C$38*(1+$H$20)^(A41-$A$38) -> 78805.766 | D41: 0 | E41: =$E$38*(1+$H$23)^(A41-$A$38) -> 1423828.1 | F41: =$F$38*(1+$H$20)^(A41-$A$38) -> 96200.885 | G41: =$G$38*(1+$H$20)^(A41-$A$38) -> 377980.67 | H41: =$H$38*(1+$H$20)^(A41-$A$38) -> 804568.69 | I41: =$I$38*(1+$H$23)^((A41-$A$38)) -> 1062175.8 | J41: =$J$38*(1+$H$23)^((A41-$A$38)) -> 797577.02 | K41: =$K$38*(1+$H$20)^(A41-$A$38) -> 3447283 | L41: =$L$38*(1+$H$24)^(A41-$A$38) -> 3991890.8 | M41: =$M$38*(1+$H$22)^((A41-$A$38)) -> 5576665.3 | N41: pcs
A42: 2026 | B42: =$B$38*($H$21+1)^(A42-$A$38) -> 1544213.3 | C42: =$C$38*(1+$H$20)^(A42-$A$38) -> 92202.746 | D42: 0 | E42: =$E$38*(1+$H$23)^(A42-$A$38) -> 1601806.6 | F42: =$F$38*(1+$H$20)^(A42-$A$38) -> 112555.04 | G42: =$G$38*(1+$H$20)^(A42-$A$38) -> 442237.38 | H42: =$H$38*(1+$H$20)^(A42-$A$38) -> 941345.37 | I42: =$I$38*(1+$H$23)^((A42-$A$38)) -> 1194947.8 | J42: =$J$38*(1+$H$23)^((A42-$A$38)) -> 897274.14 | K42: =$K$38*(1+$H$20)^(A42-$A$38) -> 4033321.1 | L42: =$L$38*(1+$H$24)^(A42-$A$38) -> 4430998.8 | M42: =$M$38*(1+$H$22)^((A42-$A$38)) -> 6067411.9 | N42: pcs
A43: 2027 | B43: =$B$38*($H$21+1)^(A43-$A$38) -> 1605981.8 | C43: =$C$38*(1+$H$20)^(A43-$A$38) -> 107877.21 | D43: 0 | E43: =$E$38*(1+$H$23)^(A43-$A$38) -> 1802032.5 | F43: =$F$38*(1+$H$20)^(A43-$A$38) -> 131689.39 | G43: =$G$38*(1+$H$20)^(A43-$A$38) -> 517417.74 | H43: =$H$38*(1+$H$20)^(A43-$A$38) -> 1101374.1 | I43: =$I$38*(1+$H$23)^((A43-$A$38)) -> 1344316.2 | J43: =$J$38*(1+$H$23)^((A43-$A$38)) -> 1009433.4 | K43: =$K$38*(1+$H$20)^(A43-$A$38) -> 4718985.7 | L43: =$L$38*(1+$H$24)^(A43-$A$38) -> 4918408.7 | M43: =$M$38*(1+$H$22)^((A43-$A$38)) -> 6601344.1 | N43: pcs
A44: 2028 | B44: =$B$38*($H$21+1)^(A44-$A$38) -> 1670221.1 | C44: =$C$38*(1+$H$20)^(A44-$A$38) -> 126216.34 | D44: 0 | E44: =$E$38*(1+$H$23)^(A44-$A$38) -> 2027286.5 | F44: =$F$38*(1+$H$20)^(A44-$A$38) -> 154076.59 | G44: =$G$38*(1+$H$20)^(A44-$A$38) -> 605378.75 | H44: =$H$38*(1+$H$20)^(A44-$A$38) -> 1288607.7 | I44: =$I$38*(1+$H$23)^((A44-$A$38)) -> 1512355.8 | J44: =$J$38*(1+$H$23)^((A44-$A$38)) -> 1135612.6 | K44: =$K$38*(1+$H$20)^(A44-$A$38) -> 5521213.3 | L44: =$L$38*(1+$H$24)^(A44-$A$38) -> 5459433.6 | M44: =$M$38*(1+$H$22)^((A44-$A$38)) -> 7182262.4 | N44: pcs
A45: 2029 | B45: =$B$38*($H$21+1)^(A45-$A$38) -> 1737029.9 | C45: =$C$38*(1+$H$20)^(A45-$A$38) -> 147673.12 | D45: 0 | E45: =$E$38*(1+$H$23)^(A45-$A$38) -> 2280697.3 | F45: =$F$38*(1+$H$20)^(A45-$A$38) -> 180269.61 | G45: =$G$38*(1+$H$20)^(A45-$A$38) -> 708293.14 | H45: =$H$38*(1+$H$20)^(A45-$A$38) -> 1507671 | I45: =$I$38*(1+$H$23)^((A45-$A$38)) -> 1701400.2 | J45: =$J$38*(1+$H$23)^((A45-$A$38)) -> 1277564.2 | K45: =$K$38*(1+$H$20)^(A45-$A$38) -> 6459819.5 | L45: =$L$38*(1+$H$24)^(A45-$A$38) -> 6059971.3 | M45: =$M$38*(1+$H$22)^((A45-$A$38)) -> 7814301.5 | N45: pcs
A46: 2030 | B46: =$B$38*($H$21+1)^(A46-$A$38) -> 1806511.1 | C46: =$C$38*(1+$H$20)^(A46-$A$38) -> 172777.55 | D46: 0 | E46: =$E$38*(1+$H$23)^(A46-$A$38) -> 2565784.5 | F46: =$F$38*(1+$H$20)^(A46-$A$38) -> 210915.44 | G46: =$G$38*(1+$H$20)^(A46-$A$38) -> 828702.97 | H46: =$H$38*(1+$H$20)^(A46-$A$38) -> 1763975 | I46: =$I$38*(1+$H$23)^((A46-$A$38)) -> 1914075.2 | J46: =$J$38*(1+$H$23)^((A46-$A$38)) -> 1437259.7 | K46: =$K$38*(1+$H$20)^(A46-$A$38) -> 7557988.8 | L46: =$L$38*(1+$H$24)^(A46-$A$38) -> 6726568.2 | M46: =$M$38*(1+$H$22)^((A46-$A$38)) -> 8501960 | N46: pcs
...

Sheet Material demand scenarion
A1: Region | B1: Technology | C1: Material | D1: Scenario | E1: Unit | F1: 2020 | G1: 2030 | H1: 2050 | I1: Source | J1: for validation | K1: share on current production (2022) | M1: CO2 - reduction scneario
A2: EU | B2: Heat pumps | C2: Cu | D2: LDS | E2: t/yr | F2: 59658 | G2: 154180.03 | H2: 233490.3 | I2: Source Carrara et al. 2024 | M2: Country | N2: Copper emissions reudction
A3: EU | B3: Heat pumps | C3: Cu | D3: HDS | E3: t/yr | F3: 59658 | G3: 369093.99 | H3: 584188.6 | I3: Source Carrara et al. 2025 | N3: 2030 | O3: 2050
A4: EU | B4: Heat pumps | C4: Plastic | D4: LDS | E4: t/yr | F4: 0.003779 | G4: 0.9138384 | H4: 1.7557812 | I4: Source Carrara et al. 2026 | M4: Europe | N4: 30-40% | O4: 90 - 97$% | P4: https://internationalcopper.org/wp-content/uploads/2023/03/Copper_The-Pathway-to-Net-Zero_Focus-on-Europe_final.pdf
A5: EU | B5: Heat pumps | C5: Plastic | D5: HDS | E5: t/yr | F5: 0.003779 | G5: 2.1826816 | H5: 6.7155031 | I5: Source Carrara et al. 2027 | P5: https://internationalcopper.org/wp-content/uploads/2023/02/ICA-GlobalDecarbonization-202301-Final-singlepgs.pdf
A6: EU | B6: Heat pumps | C6: Steel | D6: LDS | E6: t/yr | F6: 0.019222 | G6: 0.9138384 | H6: 1.7557812 | I6: Source Carrara et al. 2028
A7: EU | B7: Heat pumps | C7: Steel | D7: HDS | E7: t/yr | F7: 0.019222 | G7: 2.1826816 | H7: 6.7155031 | I7: Source Carrara et al. 2029
A8: USA | B8: Heat pumps | C8: Cu | D8: LDS | E8: t/yr | F8: 125172 | G8: 133658.84 | H8: 151841.65 | I8: Source Carrara et al. 2030
A9: USA | B9: Heat pumps | C9: Cu | D9: HDS | E9: t/yr | F9: 125172 | G9: 232583.43 | H9: 312724.66 | I9: Source Carrara et al. 2031
A10: USA | B10: Heat pumps | C10: Plastic | D10: LDS | E10: t/yr | F10: 61902 | G10: 66099.042 | H10: 75091.089 | I10: Source Carrara et al. 2032
A11: USA | B11: Heat pumps | C11: Plastic | D11: HDS | E11: t/yr | F11: 61902 | G11: 115020.77 | H11: 154653.45 | I11: Source Carrara et al. 2033
A12: USA | B12: Heat pumps | C12: Steel | D12: LDS | E12: t/yr | F12: 536940 | G12: 573345.28 | H12: 651342.6 | I12: Source Carrara et al. 2034
A13: USA | B13: Heat pumps | C13: Steel | D13: HDS | E13: t/yr | F13: 536940 | G13: 997693.96 | H13: 1341469.2 | I13: Source Carrara et al. 2035
A14: China | B14: Heat pumps | C14: Cu | D14: LDS | E14: t/yr | F14: 71004 | G14: 81768.074 | H14: 85804.319 | I14: Source Carrara et al. 2036
A15: China | B15: Heat pumps | C15: Cu | D15: HDS | E15: t/yr | F15: 71004 | G15: 136862.39 | H15: 199519.86 | I15: Source Carrara et al. 2037
A16: China | B16: Heat pumps | C16: Plastic | D16: LDS | E16: t/yr | F16: 35114 | G16: 40437.217 | H16: 42433.284 | I16: Source Carrara et al. 2038
A17: China | B17: Heat pumps | C17: Plastic | D17: HDS | E17: t/yr | F17: 35114 | G17: 67683.315 | H17: 98669.658 | I17: Source Carrara et al. 2039
... A25: World | B25: Heat pumps | C25: Steel | D25: HDS | E25: t/yr | F25: 1411430 | G25: 3496762.4 | H25: 5062190.8 | I25: Source Carrara et al. 2047
A27: World | B27: 2020 | C27: 2030 | D27: max_laod
A28: Copper | B28: =F21/SUM('Refinement (material production'!L35:L46)/1000 -> 0.012647663 | C28: =conversion!G33/SUM('Refinement (material production'!L35:L46) -> 0.079804987 | D28: =C28*1.1 -> 0.087785486
A29: Steel | B29: =F19/SUM('Refinement (material production'!AB34:AB45)/10^6 -> 0.00016030526 | C29: =SUM(conversion!G32)/SUM('Refinement (material production'!$AB$34:$AB$45)/10^3 -> 0.0037002931 | D29: =C29*1.1 -> 0.0040703224
A30: Iron | C30: ='Material demand scenarion'!G25*1.6/SUM(mining!K63:K74)/10^6 -> 0.0021518538 | D30: =C30*1.1 -> 0.0023670392
A31: Nickel | C31: =conversion!G34/SUM(mining!K45:K56)*10^3 -> 0.069067486 | D31: =C31*1.1 -> 0.075974235
A32: Aluminium | C32: =conversion!G31/SUM('Refinement (material production'!B35:B46) -> 0.022214689 | D32: =C32*1.1 -> 0.024436157
A33: Bauxite | C33: =conversion!G31*4/SUM(mining!J3:J14) -> 0.015994576 | D33: =C33*1.1 -> 0.017594033

Sheet Allocation OPEX CAPEX
A1: Allocation OPEX HX and Compressor
A3: Material cost | F3: OPEX variable for Compressor and HEX manufacturing | J3: Assumptions | O3: Allocation based on weight principle | P3: kg/kW | Q3: %
A4: air - air CHN | B4: 77.765283 | C4: USD/kW | D4: IEA 2024 | J4: share material on total cost | K4: 0.9 | L4: see ENEL 2023 | O4: total weight input Hx | P4: =conversion!D31+conversion!D34 -> 4.643125 | Q4: =P4/$P$6 -> 0.34964936
A5: air - water CHN | B5: 90.624118 | C5: USD/kW | D5: IEA 2024 | J5: Allocation factor HX | K5: 0.34964936 | L5: based on weight | O5: total weight input compressor | P5: =conversion!D35+conversion!D37 -> 8.63625 | Q5: =P5/$P$6 -> 0.65035064
A6: air - air home EU | B6: 111.51972 | C6: USD/kW | D6: IEA 2024 | J6: Allocation Factor Compresso r | K6: 0.65035064 | L6: based on weight | O6: total weight input materials | P6: =SUM(P4:P5) -> 13.279375
A7: air - water EU | B7: 195.10215 | C7: USD/kW | D7: IEA 2024
A8: air - air JPN | B8: 68.121157 | C8: USD/kW | D8: IEA 2024 | J8: Regionalized cost factors | O8: Share Copper in Component/HP | P8: =conversion!B35/conversion!B33 -> 0.25808157 | U8: Australia | V8: 1.3895082 | W8: 1.0573199
A9: air - water JPN | B9: 195.10215 | C9: USD/kW | D9: IEA 2024 | J9: For Labour | K9: €/h | L9: Labour adjusment factor | M9: For countries in EU | O9: Share Steel in Component/HP | P9: =conversion!B37/conversion!B32 -> 0.3860823 | U9: Austria | V9: 1.4386267 | W9: 1.394268
A10: air air CHN | B10: 54.927706 | C10: USD/kW | D10: IEA 2024 | J10: Australia | K10: 38.19 | L10: =K10/$K$20 -> 1.3895082 | U10: Brazil | V10: 0.29034499 | W10: 0.59643687
A11: air air USA | B11: 178.12634 | C11: USD/kW | D11: IEA 2024 | J11: Austria | K11: 39.54 | L11: =K11/$K$20 -> 1.4386267 | M11: =K11/$K$19 -> 1.4326087 | O11: Cost Copper in HP total | P11: =16.7*0.84 -> 14.028 | Q11: €/kW | R11: ENEL | U11: China | V11: 0.48390831 | W11: 0.3020914
A12: air air India | B12: 56.947355 | C12: USD/kW | D12: IEA 2024 | J12: Brazil | K12: 7.98 | L12: =K12/$K$20 -> 0.29034499 | O12: Cost Steel in HP total | P12: =8.6*0.84 -> 7.224 | Q12: €/kW | R12: ENEL | U12: Czech republic | V12: 0.38967354 | W12: 1.390395
J13: China | K13: =K21/3 -> 13.3 | L13: =K13/$K$20 -> 0.48390831 | U13: Germany | V13: 1.5710647 | W13: 1.4136328
A14: average value for technologies | B14: Material Cost | C14: Only Component cost minus steel and copper | D14: share affected by labor | E14: total cost with adjusted labor cost | F14: Assumed allocation to Compressor | G14: Assumed allocation to HEX | J14: Czech republic | K14: 10.71 | L14: =K14/$K$20 -> 0.38967354 | M14: =K14/$K$19 -> 0.38804348 | U14: Italy | V14: 1.1821189 | W14: 1.7699458
A15: AUS | B15: =114.248442448875*0.84 -> 95.968692 | C15: =B15-$P$11-$P$12 -> 74.716692 | D15: =C15/$K$4-C15 -> 8.3018546 | E15: =D15*L10+C15 -> 86.252186 | F15: =E15*$K$6 -> 56.094164 | G15: =E15*$K$5 -> 30.158022 | H15: €/kW | J15: Germany | K15: 43.18 | L15: =K15/$K$20 -> 1.5710647 | M15: =K15/$K$19 -> 1.5644928 | O15: average enrgy cost per kW | U15: Japan | V15: 0.96272285 | W15: 0.85592564
A16: AUT | B16: =161.582737600832*0.84 -> 135.7295 | C16: =B16-$P$11-$P$12 -> 114.4775 | D16: =C16/$K$4-C16 -> 12.719722 | E16: =D16*L11+C16 -> 132.77643 | F16: =E16*$K$6 -> 86.351237 | G16: =E16*$K$5 -> 46.425194 | H16: €/kW | J16: Italy | K16: 32.49 | L16: =K16/$K$20 -> 1.1821189 | M16: =K16/$K$19 -> 1.1771739 | O16: eu | P16: 6.4 | Q16: €/kW | R16: EU Hydronic report | U16: Korea | V16: 0.83610624 | W16: 0.50735864
A17: BRA | B17: =114.248442448875*0.84 -> 95.968692 | C17: =B17-$P$11-$P$12 -> 74.716692 | D17: =C17/$K$4-C17 -> 8.3018546 | E17: =D17*L12+C17 -> 77.127094 | F17: =E17*$K$6 -> 50.159654 | G17: =E17*$K$5 -> 26.967439 | H17: €/kW | J17: Japan | K17: 26.46 | L17: =K17/$K$20 -> 0.96272285 | O17: china | P17: 4.6 | Q17: €/kW | R17: EU Hydronic report | U17: Rest of Europe | V17: 1.0042007 | W17: 1
A18: CHN | B18: =AVERAGE(B4:B5,B10)*0.84 -> 62.52879 | C18: =B18-$P$11-$P$12 -> 41.27679 | D18: =C18/$K$4-C18 -> 4.58631 | E18: =D18*L13+C18 -> 43.496143 | F18: =E18*$K$6 -> 28.287745 | G18: =E18*$K$5 -> 15.208399 | H18: €/kW | J18: Korea | K18: 22.98 | L18: =K18/$K$20 -> 0.83610624 | O18: usa | P18: 2.7 | Q18: €/kW | R18: EU Hydronic report | U18: Rest of World | V18: 1 | W18: 1
A19: CZE | B19: =161.582737600832*0.84 -> 135.7295 | C19: =B19-$P$11-$P$12 -> 114.4775 | D19: =C19/$K$4-C19 -> 12.719722 | E19: =D19*L14+C19 -> 119.43404 | F19: =E19*$K$6 -> 77.674003 | G19: =E19*$K$5 -> 41.760035 | H19: €/kW | J19: Rest of Europe | K19: 27.6 | L19: =K19/$K$20 -> 1.0042007 | P19: =AVERAGE(P16:P18) -> 4.5666667 | U19: USA | V19: 1.4517249 | W19: 0.71262587
A20: DEU | B20: =161.582737600832*0.84 -> 135.7295 | C20: =B20-$P$11-$P$12 -> 114.4775 | D20: =C20/$K$4-C20 -> 12.719722 | E20: =D20*L15+C20 -> 134.46101 | F20: =E20*$K$6 -> 87.446801 | G20: =E20*$K$5 -> 47.014205 | H20: €/kW | J20: Rest of World | K20: =AVERAGE(K10:K19,K21) -> 27.484545 | L20: =K20/$K$20 -> 1
A21: ITA | B21: =161.582737600832*0.84 -> 135.7295 | C21: =B21-$P$11-$P$12 -> 114.4775 | D21: =C21/$K$4-C21 -> 12.719722 | E21: =D21*L16+C21 -> 129.51372 | F21: =E21*$K$6 -> 84.229333 | G21: =E21*$K$5 -> 45.284391 | H21: €/kW | J21: USA | K21: 39.9 | L21: =K21/$K$20 -> 1.4517249
A22: JPN | B22: =AVERAGE(B8:B9) -> 131.61165 | C22: =B22-$P$11-$P$12 -> 110.35965 | D22: =C22/$K$4-C22 -> 12.262184 | E22: =D22*L17+C22 -> 122.16474 | F22: =E22*$K$6 -> 79.449915 | G22: =E22*$K$5 -> 42.714823 | H22: €/kW | L22: =MIN(L10:L21) -> 0.29034499 | M22: Brazil
A23: KOR | B23: =114.248442448875*0.84 -> 95.968692 | C23: =B23-$P$11-$P$12 -> 74.716692 | D23: =C23/$K$4-C23 -> 8.3018546 | E23: =D23*L18+C23 -> 81.657924 | F23: =E23*$K$6 -> 53.106283 | G23: =E23*$K$5 -> 28.551641 | H23: €/kW | L23: =MAX(L10:L22) -> 1.5710647 | M23: Germany | O23: Allocation for CAPEX
A24: ROE | B24: =AVERAGE((B6:B7))*0.84 -> 128.78119 | C24: =B24-$P$11-$P$12 -> 107.52919 | D24: =C24/$K$4-C24 -> 11.947688 | E24: =D24*L19+C24 -> 119.52706 | F24: =E24*$K$6 -> 77.734502 | G24: =E24*$K$5 -> 41.792562 | H24: €/kW | J24: For Energy Cost | K24: USD/kWh | L24: Energy adjusment factor | O24: Total OPEX | P24: Part of HP | Q24: Share compressor | R24: Share HEX
A25: ROW | B25: =AVERAGE(B4:B12)*0.84 -> 95.968692 | C25: =B25-$P$11-$P$12 -> 74.716692 | D25: =C25/$K$4-C25 -> 8.3018546 | E25: =D25*L20+C25 -> 83.018546 | F25: =E25*$K$6 -> 53.991165 | G25: =E25*$K$5 -> 29.027382 | H25: €/kW | J25: Australia | K25: 0.273 | L25: =K25/$K$35 -> 1.0573199 | O25: =E15+E54+B40 -> 143.56132 | P25: =(E54+B40)/O25 -> 0.39919621 | Q25: =F15/O25 -> 0.39073313 | R25: =G15/O25 -> 0.21007066
A26: USA | B26: =B11*0.84 -> 149.62612 | C26: =B26-$P$11-$P$12 -> 128.37412 | D26: =C26/$K$4-C26 -> 14.263792 | E26: =D26*L21+C26 -> 149.08123 | F26: =E26*$K$6 -> 96.95507 | G26: =E26*$K$5 -> 52.126155 | H26: €/kW | J26: Austria | K26: 0.36 | L26: =K26/$K$35 -> 1.394268 | O26: =E16+E55+B41 -> 218.57146 | P26: =(E55+B41)/O26 -> 0.39252621 | Q26: =F16/O26 -> 0.39507097 | R26: =G16/O26 -> 0.21240282
J27: Brazil | K27: 0.154 | L27: =K27/$K$35 -> 0.59643687 | O27: =E17+E56+B42 -> 129.07845 | P27: =(E56+B42)/O27 -> 0.40247892 | Q27: =F17/O27 -> 0.38859821 | R27: =G17/O27 -> 0.20892286
A28: FIXED OPEX | B28: only OPEX FIXED | C28: OPEX and labor cost | F28: OPEX fixed and variable For Heat Pump Assemble | J28: China | K28: 0.078 | L28: =K28/$K$35 -> 0.3020914 | O28: =E18+E57+B43 -> 78.923834 | P28: =(E57+B43)/O28 -> 0.44888456 | Q28: =F18/O28 -> 0.35841828 | R28: =G18/O28 -> 0.19269716
A29: air air CHN | B29: 13.784876 | C29: 29.539021 | D29: USD/kW | E29: IEA 2024 | F29: =C29-B29 -> 15.754144 | J29: Czech republic | K29: 0.359 | L29: =K29/$K$35 -> 1.390395 | O29: =E19+E58+B44 -> 201.99159 | P29: =(E58+B44)/O29 -> 0.40871776 | Q29: =F19/O29 -> 0.38454078 | R29: =G19/O29 -> 0.20674146
A30: air air CHN | B30: 11.815608 | C30: 11.815608 | D30: USD/kW | E30: IEA 2024 | F30: =C30-B30 -> 0 | J30: Germany | K30: 0.365 | L30: =K30/$K$35 -> 1.4136328 | O30: =E20+E59+B45 -> 220.76633 | P30: =(E59+B45)/O30 -> 0.39093517 | Q30: =F20/O30 -> 0.3961057 | R30: =G20/O30 -> 0.21295913
A31: air water CHN | B31: 15.754144 | C31: 29.539021 | D31: USD/kW | E31: IEA 2024 | F31: =C31-B31 -> 13.784876 | J31: Italy | K31: 0.457 | L31: =K31/$K$35 -> 1.7699458 | O31: =E21+E60+B46 -> 216.46251 | P31: =(E60+B46)/O31 -> 0.40168059 | Q31: =F21/O31 -> 0.38911741 | R31: =G21/O31 -> 0.209202
A32: air air EU | B32: 51.200969 | C32: 76.801454 | D32: USD/kW | E32: IEA 2024 | F32: =C32-B32 -> 25.600485 | J32: Japan | K32: 0.221 | L32: =K32/$K$35 -> 0.85592564 | O32: =E22+E61+B47 -> 182.2735 | P32: =(E61+B47)/O32 -> 0.32977235 | Q32: =F22/O32 -> 0.43588298 | R32: =G22/O32 -> 0.23434467
A33: air water EU | B33: 76.801454 | C33: 131.94096 | D33: USD/kW | E33: IEA 2024 | F33: =C33-B33 -> 55.139506 | J33: Korea | K33: 0.131 | L33: =K33/$K$35 -> 0.50735864 | O33: =E23+E62+B48 -> 134.61859 | P33: =(E62+B48)/O33 -> 0.39341272 | Q33: =F23/O33 -> 0.39449443 | R33: =G23/O33 -> 0.21209286
A34: air air USA | B34: 33.477557 | C34: 70.89365 | D34: USD/kW | E34: IEA 2024 | F34: =C34-B34 -> 37.416093 | J34: Rest of Europe | K34: =AVERAGE(K25:K33,K36) -> 0.2582 | L34: =K34/$K$35 -> 1 | O34: =E24+E63+B49 -> 201.98754 | P34: =(E63+B49)/O34 -> 0.40824536 | Q34: =F24/O34 -> 0.38484801 | R34: =G24/O34 -> 0.20690663
A35: air air JPN | B35: 17.723413 | C35: 37.416093 | D35: USD/kW | E35: IEA 2024 | F35: =C35-B35 -> 19.692681 | J35: Rest of World | K35: =AVERAGE(K25:K34,K36) -> 0.2582 | L35: =K35/$K$35 -> 1 | O35: =E25+E64+B50 -> 138.90811 | P35: =(E64+B50)/O35 -> 0.40234918 | Q35: =F25/O35 -> 0.38868259 | R35: =G25/O35 -> 0.20896823
A36: air water Jon | B36: 59.078042 | C36: 86.647794 | D36: USD/kW | E36: IEA 2024 | F36: =C36-B36 -> 27.569753 | J36: USA | K36: 0.184 | L36: =K36/$K$35 -> 0.71262587 | O36: =E26+E65+B51 -> 205.66164 | P36: =(E65+B51)/O36 -> 0.27511407 | Q36: =F26/O36 -> 0.47143002 | R36: =G26/O36 -> 0.2534559
A37: air air India | B37: 11.815608 | C37: 21.661949 | D37: USD/kW | E37: IEA 2024 | F37: =C37-B37 -> 9.8463403 | L37: 1 | M37: =MAX(L25:L36) -> 1.7699458
A39: average value for technologies | B39: FIXED OPEX | D39: total | G39: =G15/8760 -> 0.0034426966
A40: AUS | B40: =$B$50 -> 27.202156 | C40: €/kW | D40: =B40+E54 -> 57.309136 | E40: 57.309136 | G40: =G16/8760 -> 0.0052996797
A41: AUT | B41: =$B$49 -> 53.761018 | C41: €/kW | D41: =B41+E55 -> 85.795026 | E41: 85.795026 | G41: =G17/8760 -> 0.0030784748
A42: BRA | B42: =$B$50 -> 27.202156 | C42: €/kW | D42: =B42+E56 -> 51.951355 | E42: 51.951355 | G42: =G18/8760 -> 0.0017361186
...

Sheet refrigerants
A1: Refrigerant type | B1: GWP | C1: unit | D1: import limit | F1: year | G1: source | H1: notes
A2: HFC-134a | B2: 1430 | C2: kgCo2-eq /kg | F2: 2030 | G2: https://eur-lex.europa.eu/legal-content/EN/TXT/?uri=uriserv:OJ.L_.2014.150.01.0195.01.ENG | H2: global phase ot of HFC ubntil 2030 (montreal protocol), he phase-down is being managed through an annual import quota that will gradually reduce over 18 years. The end point of the phase-down, 15% of the baseline level, will be reached on 1 January 2036.
A3: R410A | B3: 2088 | C3: kgCo2-eq /kg | G3: https://www.infraserv.com/de/leistungen/facility-management/expertenwissen/f-gase/kaeltemittel/spezifische-kaeltemittel/r-410a.html
A4: R 32 | B4: 675 | C4: kgCo2-eq /kg | G4: https://www.infraserv.com/de/leistungen/facility-management/expertenwissen/f-gase/kaeltemittel/spezifische-kaeltemittel/r-410a.html
A5: R 290 | B5: 3 | C5: kgCo2-eq /kg | G5: https://www.infraserv.com/de/leistungen/facility-management/expertenwissen/f-gase/kaeltemittel/spezifische-kaeltemittel/r-410a.html | H5: Propane
A6: CO2 | B6: 1 | C6: kgCo2-eq /kg
A8: Mittelwert between most common types | B8: =AVERAGE(B2:B4) -> 1397.6667
A9: Country | B9: Production | C9: Capacity | D9: Units | E9: converted to t | F9: type | G9: year | H9: source | I9: note | M9: 2022 Calculated HFC Production | O9: Source | P9: https://www.epa.gov/climate-hfcs-reduction/2022-hfc-data-hub/expanded-hfc-data#2022%20Calc%20Prod
A10: China | B10: 811000 | C10: =1683*10^6 -> 1683000000 | D10: t | E10: =B10 -> 811000 | F10: HFC | G10: 2020 | H10: https://chineseclimatepolicy.oxfordenergy.org/book-content/domestic-policies/hfcs/#:~:text=Capacity%20utilization%20in%20the%20Chinese,actual%20production%20of%20811%2C000%20tonnes. | I10: global share 70% | M10: USA: | N10: Chemical | O10: Total Production (MT) | P10: Production for Feedstock (MT) | Q10: Destruction (MT) | R10: Calculated Production (MT) | S10: Calculated Production (MTCO2e)
A11: China | B11: 1581392661 | D11: tCO2-eq | E11: =B11/$T$23 -> 1178727.7 | G11: 2023 | H11: https://ozone.unep.org/countries/profile/chn
A12: Australia | B12: 0 | C12: 0 | F12: HFC | G12: 2023 | H12: https://ozone.unep.org/countries/profile/aus | I12: negative production??? | N12: HFC-32 | O12: 17762 | P12: 0 | Q12: 17.7 | R12: 17744.3 | S12: 11977388
A13: USA | B13: =R16/1.103 -> 55645.422 | D13: t | F13: HFC-134a | G13: 2022 | H13: https://www.epa.gov/climate-hfcs-reduction/2022-hfc-data-hub/expanded-hfc-data#2022%20Calc%20Prod | N13: HFC-41 | O13: 25.4 | P13: 1.6 | Q13: 1.8 | R13: 22 | S13: 2027.6
A14: USA | B14: =R23 -> 133907.2 | D14: t | E14: 133907.2 | F14: HFC | G14: 2022 | H14: https://www.epa.gov/climate-hfcs-reduction/2022-hfc-data-hub/expanded-hfc-data#2022%20Calc%20Prod | N14: HFC-125 | O14: 19223.1 | P14: 0 | Q14: 47.4 | R14: 19175.7 | S14: 67115021
A15: France | B15: 15518000 | D15: MT CO2-eq | E15: =B15/$T$23 -> 11566.702 | F15: HFC | G15: 2022 | H15: Global Overview of HCFC, HFC, and HFO/HCFO Production, 2022 | N15: HFC-134 | O15: 516.1 | P15: 0 | Q15: 1.8 | R15: 514.3 | S15: 565688.2
